Workbook

Sheet Inputs
A1: Input | B1: Unit | C1: Value | D1: Based on
A2: Discount rate | B2: % | C2: 0.07 | D2: Infrastructure Australia guidelines for Economic Appraisal
A3: Analysis period | B3: years | C3: 30 | D3: Assumption
A4: Analysis start year | B4: year (FY) | C4: 2026
A5: Analysis end year | B5: year (FY) | C5: =C4+30 -> 2056
A6: Oaky Creek Road length | B6: km | C6: 17
A7: Percy Road length | B7: km | C7: 4.5
A8: Total road length | B8: km | C8: =SUM(C6:C7) -> 21.5
A9: No. of stream crossings per km | B9: No. | C9: 1
A10: Oaky Creek Road no. of km (crest to crest) stream crossings | B10: km | C10: 7.098
A11: Percy Road no. of km (crest to crest) stream crossings | B11: km | C11: 2.907
A12: Total no. of kms (crest to crest) stream crossings | B12: km | C12: =SUM(C10:C11) -> 10.005
A13: Capital costs
A14: Concrete floodway | B14: AUD$/crossing | C14: 60000 | D14: Provided by Cook Shire Council, applied to Scenarios 3,4
A15: Rock floodway | B15: AUD$/crossing | C15: 30000 | D15: Provided by Cook Shire Council, applied to Scenarios 3,4
A16: Rock mulch, rock grade control structures, and gully rock chutes | B16: AUD$/crossing | C16: 25000 | D16: Provided by Cook Shire Council, applied to Scenarios 3,4
A17: Bitumen dust seal | B17: AUD$/km | C17: 110000 | D17: Provided by Cook Shire Council, applied to Scenario 4
A18: Grading to prepare road surface for bitumen dust seal | B18: AUD$/km | C18: 5000 | D18: Provided by Cook Shire Council, applied to Scenario 4
A19: Ongoing costs
A20: Business-as-usual maintenance Oaky Creek Road | B20: AUD$/km/year | C20: 19720 | D20: Provided by Cook Shire Council, applied to Scenario 1
A21: Business-as-usual maintenance Percy Road | B21: AUD$/km/year | C21: 19888 | D21: Provided by Cook Shire Council, applied to Scenario 1
A22: % of business-as-usual maintenance costs in Alternative Maintenance scenario | B22: % | C22: 70 | D22: Provided by Cook Shire Council, applied to Scenario 1
A23: % of business-as-usual maintenance costs in Major Erosion Control scenario | B23: % | C23: 70 | D23: Provided by Cook Shire Council, applied to Scenario 1
A24: Invasive grader grass spraying (non-selective herbicides)
A25: Year 1 and 2 | B25: AUD$/km/year | C25: 1500 | D25: Provided by Cook Shire Council, applied to Scenarios 2,3
A26: Year 3 onwards | B26: AUD$/km/year | C26: 800 | D26: Provided by Cook Shire Council, applied to Scenarios 2,3
A27: Woody weeds (broadleaf herbicide)
A28: Year 1 | B28: AUD$/km/year | C28: 2705 | D28: Provided by Cook Shire Council, applied to Scenarios 2,3
A29: Year 2 follow up | B29: AUD$/km/year | C29: 1122 | D29: Provided by Cook Shire Council, applied to Scenarios 2,3
A30: Year 3 follow up | B30: AUD$/km/year | C30: 650 | D30: Provided by Cook Shire Council, applied to Scenarios 2,3
A31: Year 4 onwards | B31: AUD$/km/year | C31: 400 | D31: Provided by Cook Shire Council, applied to Scenarios 2,3
A32: Maintenance of bitumen dust seal | B32: AUD$/km/year r | C32: 5500 | D32: Provided by Cook Shire Council, applied to Scenario 4
A33: Drain cleaning in Full Betterment scenario | B33: AUD$/km/year | C33: 200 | D33: Provided by Cook Shire Council, applied to Scenario 4
A34: Erosion rates
A35: Scenario 1: business-as-usual | B35: tons/km/year < 20 µm | C35: 55.3 | D35: Shellberg, et al. (2026)
A36: Scenario 2: alternative maintenance | B36: tons/km/year < 20 µm | C36: 46.5 | D36: Shellberg, et al. (2026)
A37: Scenario 3: major erosion control | B37: tons/km/year < 20 µm | C37: 31.7 | D37: Shellberg, et al. (2026)
A38: Scenario 4: full betterment | B38: tons/km/year < 20 µm | C38: 17.6 | D38: Shellberg, et al. (2026)
A39: Avoided abatement costs
A40: Avoided abatement cost value (FY2024 dollars) | B40: AUD$/ton/year | C40: =1624 -> 1624 | D40: Doshi, et al (2026), indexed to 2026 dollars
...

Sheet DCF
A1: Cost-Benefit Analysis — Unsealed Roads: Simplified Discounted Cash Flow
A4: Key parameters
A5: Discount rate | B5: =Inputs!C2 -> 0.07
A6: Analysis period (years) | B6: =Inputs!C3 -> 30
A7: Total road length (km) | B7: =Inputs!C8 -> 21.5
A8: Stream crossings treated (no.) | B8: =Inputs!C9*Inputs!C12 -> 10.005
A9: Crest-to-crest crossing length (km) | B9: =Inputs!C12 -> 10.005
A10: Sediment abatement value ($/t <20µm, FY2026 dollars) | B10: =Inputs!C42 -> 1721.112
A11: Maintenance in Scenarios 2 & 3 (% of BAU) | B11: =Inputs!C22/100 -> 0.7
B13: Present value | C13: =Inputs!C4 -> 2026 | D13: =C13+1 -> 2027 | E13: =D13+1 -> 2028 | F13: =E13+1 -> 2029 | G13: =F13+1 -> 2030 | H13: =G13+1 -> 2031 | I13: =H13+1 -> 2032 | J13: =I13+1 -> 2033 | K13: =J13+1 -> 2034 | ... AF13: =AE13+1 -> 2055
A14: Discount factor | C14: =1/(1+$B$5)^(C$13-Inputs!$C$4) -> 1 | D14: =1/(1+$B$5)^(D$13-Inputs!$C$4) -> 0.93457944 | E14: =1/(1+$B$5)^(E$13-Inputs!$C$4) -> 0.87343873 | F14: =1/(1+$B$5)^(F$13-Inputs!$C$4) -> 0.81629788 | G14: =1/(1+$B$5)^(G$13-Inputs!$C$4) -> 0.76289521 | H14: =1/(1+$B$5)^(H$13-Inputs!$C$4) -> 0.71298618 | I14: =1/(1+$B$5)^(I$13-Inputs!$C$4) -> 0.66634222 | J14: =1/(1+$B$5)^(J$13-Inputs!$C$4) -> 0.62274974 | ... AF14: =1/(1+$B$5)^(AF$13-Inputs!$C$4) -> 0.14056282
A16: Scenario 1: Business-as-usual (base case)
A17: Maintenance — Oaky Creek Road | B17: =SUMPRODUCT(C17:AF17,$C$14:$AF$14) -> 4451207.5 | C17: =Inputs!$C$20*Inputs!$C$6 -> 335240 | D17: =Inputs!$C$20*Inputs!$C$6 -> 335240 | E17: =Inputs!$C$20*Inputs!$C$6 -> 335240 | F17: =Inputs!$C$20*Inputs!$C$6 -> 335240 | G17: =Inputs!$C$20*Inputs!$C$6 -> 335240 | H17: =Inputs!$C$20*Inputs!$C$6 -> 335240 | I17: =Inputs!$C$20*Inputs!$C$6 -> 335240 | J17: =Inputs!$C$20*Inputs!$C$6 -> 335240 | ... AF17: =Inputs!$C$20*Inputs!$C$6 -> 335240
A18: Maintenance — Percy Road | B18: =SUMPRODUCT(C18:AF18,$C$14:$AF$14) -> 1188298.7 | C18: =Inputs!$C$21*Inputs!$C$7 -> 89496 | D18: =Inputs!$C$21*Inputs!$C$7 -> 89496 | E18: =Inputs!$C$21*Inputs!$C$7 -> 89496 | F18: =Inputs!$C$21*Inputs!$C$7 -> 89496 | G18: =Inputs!$C$21*Inputs!$C$7 -> 89496 | H18: =Inputs!$C$21*Inputs!$C$7 -> 89496 | I18: =Inputs!$C$21*Inputs!$C$7 -> 89496 | J18: =Inputs!$C$21*Inputs!$C$7 -> 89496 | ... AF18: =Inputs!$C$21*Inputs!$C$7 -> 89496
A19: Total financial costs | B19: =SUMPRODUCT(C19:AF19,$C$14:$AF$14) -> 5639506.2 | C19: =SUM(C17:C18) -> 424736 | D19: =SUM(D17:D18) -> 424736 | E19: =SUM(E17:E18) -> 424736 | F19: =SUM(F17:F18) -> 424736 | G19: =SUM(G17:G18) -> 424736 | H19: =SUM(H17:H18) -> 424736 | I19: =SUM(I17:I18) -> 424736 | J19: =SUM(J17:J18) -> 424736 | ... AF19: =SUM(AF17:AF18) -> 424736
A20: Sediment delivered to reef (t/yr <20µm) | C20: =Inputs!$C$35*$B$7 -> 1188.95 | D20: =Inputs!$C$35*$B$7 -> 1188.95 | E20: =Inputs!$C$35*$B$7 -> 1188.95 | F20: =Inputs!$C$35*$B$7 -> 1188.95 | G20: =Inputs!$C$35*$B$7 -> 1188.95 | H20: =Inputs!$C$35*$B$7 -> 1188.95 | I20: =Inputs!$C$35*$B$7 -> 1188.95 | J20: =Inputs!$C$35*$B$7 -> 1188.95 | ... AF20: =Inputs!$C$35*$B$7 -> 1188.95
A21: Cost of sediment delivery to the reef | B21: =SUMPRODUCT(C21:AF21,$C$14:$AF$14) -> 27170318 | C21: =C20*$B$10 -> 2046316.1 | D21: =D20*$B$10 -> 2046316.1 | E21: =E20*$B$10 -> 2046316.1 | F21: =F20*$B$10 -> 2046316.1 | G21: =G20*$B$10 -> 2046316.1 | H21: =H20*$B$10 -> 2046316.1 | I21: =I20*$B$10 -> 2046316.1 | J21: =J20*$B$10 -> 2046316.1 | ... AF21: =AF20*$B$10 -> 2046316.1
A22: Total costs (financial + environmental) | B22: =SUMPRODUCT(C22:AF22,$C$14:$AF$14) -> 32809824 | C22: =C19+C21 -> 2471052.1 | D22: =D19+D21 -> 2471052.1 | E22: =E19+E21 -> 2471052.1 | F22: =F19+F21 -> 2471052.1 | G22: =G19+G21 -> 2471052.1 | H22: =H19+H21 -> 2471052.1 | I22: =I19+I21 -> 2471052.1 | J22: =J19+J21 -> 2471052.1 | ... AF22: =AF19+AF21 -> 2471052.1
A24: Scenario 2: Alternative maintenance
A25: Maintenance — Oaky Creek Road | B25: =SUMPRODUCT(C25:AF25,$C$14:$AF$14) -> 3115845.2 | C25: =C17*$B$11 -> 234668 | D25: =D17*$B$11 -> 234668 | E25: =E17*$B$11 -> 234668 | F25: =F17*$B$11 -> 234668 | G25: =G17*$B$11 -> 234668 | H25: =H17*$B$11 -> 234668 | I25: =I17*$B$11 -> 234668 | J25: =J17*$B$11 -> 234668 | ... AF25: =AF17*$B$11 -> 234668
A26: Maintenance — Percy Road | B26: =SUMPRODUCT(C26:AF26,$C$14:$AF$14) -> 831809.1 | C26: =C18*$B$11 -> 62647.2 | D26: =D18*$B$11 -> 62647.2 | E26: =E18*$B$11 -> 62647.2 | F26: =F18*$B$11 -> 62647.2 | G26: =G18*$B$11 -> 62647.2 | H26: =H18*$B$11 -> 62647.2 | I26: =I18*$B$11 -> 62647.2 | J26: =J18*$B$11 -> 62647.2 | ... AF26: =AF18*$B$11 -> 62647.2
A27: Invasive grader grass spraying | B27: =SUMPRODUCT(C27:AF27,$C$14:$AF$14) -> 257491.41 | C27: =IF(C$13-Inputs!$C$4<2,Inputs!$C$25,Inputs!$C$26)*$B$7 -> 32250 | D27: =IF(D$13-Inputs!$C$4<2,Inputs!$C$25,Inputs!$C$26)*$B$7 -> 32250 | E27: =IF(E$13-Inputs!$C$4<2,Inputs!$C$25,Inputs!$C$26)*$B$7 -> 17200 | F27: =IF(F$13-Inputs!$C$4<2,Inputs!$C$25,Inputs!$C$26)*$B$7 -> 17200 | G27: =IF(G$13-Inputs!$C$4<2,Inputs!$C$25,Inputs!$C$26)*$B$7 -> 17200 | H27: =IF(H$13-Inputs!$C$4<2,Inputs!$C$25,Inputs!$C$26)*$B$7 -> 17200 | I27: =IF(I$13-Inputs!$C$4<2,Inputs!$C$25,Inputs!$C$26)*$B$7 -> 17200 | J27: =IF(J$13-Inputs!$C$4<2,Inputs!$C$25,Inputs!$C$26)*$B$7 -> 17200 | ... AF27: =IF(AF$13-Inputs!$C$4<2,Inputs!$C$25,Inputs!$C$26)*$B$7 -> 17200
A28: Woody weeds (broadleaf herbicide) | B28: =SUMPRODUCT(C28:AF28,$C$14:$AF$14) -> 182947.71 | C28: =CHOOSE(MIN(C$13-Inputs!$C$4+1,4),Inputs!$C$28,Inputs!$C$29,Inputs!$C$30,Inputs!$C$31)*$B$7 -> 58157.5 | D28: =CHOOSE(MIN(D$13-Inputs!$C$4+1,4),Inputs!$C$28,Inputs!$C$29,Inputs!$C$30,Inputs!$C$31)*$B$7 -> 24123 | E28: =CHOOSE(MIN(E$13-Inputs!$C$4+1,4),Inputs!$C$28,Inputs!$C$29,Inputs!$C$30,Inputs!$C$31)*$B$7 -> 13975 | F28: =CHOOSE(MIN(F$13-Inputs!$C$4+1,4),Inputs!$C$28,Inputs!$C$29,Inputs!$C$30,Inputs!$C$31)*$B$7 -> 8600 | G28: =CHOOSE(MIN(G$13-Inputs!$C$4+1,4),Inputs!$C$28,Inputs!$C$29,Inputs!$C$30,Inputs!$C$31)*$B$7 -> 8600 | H28: =CHOOSE(MIN(H$13-Inputs!$C$4+1,4),Inputs!$C$28,Inputs!$C$29,Inputs!$C$30,Inputs!$C$31)*$B$7 -> 8600 | I28: =CHOOSE(MIN(I$13-Inputs!$C$4+1,4),Inputs!$C$28,Inputs!$C$29,Inputs!$C$30,Inputs!$C$31)*$B$7 -> 8600 | J28: =CHOOSE(MIN(J$13-Inputs!$C$4+1,4),Inputs!$C$28,Inputs!$C$29,Inputs!$C$30,Inputs!$C$31)*$B$7 -> 8600 | ... AF28: =CHOOSE(MIN(AF$13-Inputs!$C$4+1,4),Inputs!$C$28,Inputs!$C$29,Inputs!$C$30,Inputs!$C$31)*$B$7 -> 8600
A29: Total financial costs | B29: =SUMPRODUCT(C29:AF29,$C$14:$AF$14) -> 4388093.4 | C29: =SUM(C25:C28) -> 387722.7 | D29: =SUM(D25:D28) -> 353688.2 | E29: =SUM(E25:E28) -> 328490.2 | F29: =SUM(F25:F28) -> 323115.2 | G29: =SUM(G25:G28) -> 323115.2 | H29: =SUM(H25:H28) -> 323115.2 | I29: =SUM(I25:I28) -> 323115.2 | J29: =SUM(J25:J28) -> 323115.2 | ... AF29: =SUM(AF25:AF28) -> 323115.2
A30: Sediment delivered to reef (t/yr <20µm) | C30: =Inputs!$C$36*$B$7 -> 999.75 | D30: =Inputs!$C$36*$B$7 -> 999.75 | E30: =Inputs!$C$36*$B$7 -> 999.75 | F30: =Inputs!$C$36*$B$7 -> 999.75 | G30: =Inputs!$C$36*$B$7 -> 999.75 | H30: =Inputs!$C$36*$B$7 -> 999.75 | I30: =Inputs!$C$36*$B$7 -> 999.75 | J30: =Inputs!$C$36*$B$7 -> 999.75 | ... AF30: =Inputs!$C$36*$B$7 -> 999.75
A31: Cost of sediment delivery to the reef | B31: =SUMPRODUCT(C31:AF31,$C$14:$AF$14) -> 22846650 | C31: =C30*$B$10 -> 1720681.7 | D31: =D30*$B$10 -> 1720681.7 | E31: =E30*$B$10 -> 1720681.7 | F31: =F30*$B$10 -> 1720681.7 | G31: =G30*$B$10 -> 1720681.7 | H31: =H30*$B$10 -> 1720681.7 | I31: =I30*$B$10 -> 1720681.7 | J31: =J30*$B$10 -> 1720681.7 | ... AF31: =AF30*$B$10 -> 1720681.7
A32: Total costs (financial + environmental) | B32: =SUMPRODUCT(C32:AF32,$C$14:$AF$14) -> 27234744 | C32: =C29+C31 -> 2108404.4 | D32: =D29+D31 -> 2074369.9 | E32: =E29+E31 -> 2049171.9 | F32: =F29+F31 -> 2043796.9 | G32: =G29+G31 -> 2043796.9 | H32: =H29+H31 -> 2043796.9 | I32: =I29+I31 -> 2043796.9 | J32: =J29+J31 -> 2043796.9 | ... AF32: =AF29+AF31 -> 2043796.9
A34: Scenario 3: Major erosion control (betterment)
A35: Capital — concrete floodway | B35: =SUMPRODUCT(C35:AF35,$C$14:$AF$14) -> 600300 | C35: =IF(C$13=Inputs!$C$4,1,0)*Inputs!$C$14*$B$8 -> 600300 | D35: =IF(D$13=Inputs!$C$4,1,0)*Inputs!$C$14*$B$8 -> 0 | E35: =IF(E$13=Inputs!$C$4,1,0)*Inputs!$C$14*$B$8 -> 0 | F35: =IF(F$13=Inputs!$C$4,1,0)*Inputs!$C$14*$B$8 -> 0 | G35: =IF(G$13=Inputs!$C$4,1,0)*Inputs!$C$14*$B$8 -> 0 | H35: =IF(H$13=Inputs!$C$4,1,0)*Inputs!$C$14*$B$8 -> 0 | I35: =IF(I$13=Inputs!$C$4,1,0)*Inputs!$C$14*$B$8 -> 0 | J35: =IF(J$13=Inputs!$C$4,1,0)*Inputs!$C$14*$B$8 -> 0 | ... AF35: =IF(AF$13=Inputs!$C$4,1,0)*Inputs!$C$14*$B$8 -> 0
A36: Capital — rock floodway | B36: =SUMPRODUCT(C36:AF36,$C$14:$AF$14) -> 300150 | C36: =IF(C$13=Inputs!$C$4,1,0)*Inputs!$C$15*$B$8 -> 300150 | D36: =IF(D$13=Inputs!$C$4,1,0)*Inputs!$C$15*$B$8 -> 0 | E36: =IF(E$13=Inputs!$C$4,1,0)*Inputs!$C$15*$B$8 -> 0 | F36: =IF(F$13=Inputs!$C$4,1,0)*Inputs!$C$15*$B$8 -> 0 | G36: =IF(G$13=Inputs!$C$4,1,0)*Inputs!$C$15*$B$8 -> 0 | H36: =IF(H$13=Inputs!$C$4,1,0)*Inputs!$C$15*$B$8 -> 0 | I36: =IF(I$13=Inputs!$C$4,1,0)*Inputs!$C$15*$B$8 -> 0 | J36: =IF(J$13=Inputs!$C$4,1,0)*Inputs!$C$15*$B$8 -> 0 | ... AF36: =IF(AF$13=Inputs!$C$4,1,0)*Inputs!$C$15*$B$8 -> 0
A37: Capital — rock mulch, grade control structures, gully rock chutes | B37: =SUMPRODUCT(C37:AF37,$C$14:$AF$14) -> 250125 | C37: =IF(C$13=Inputs!$C$4,1,0)*Inputs!$C$16*$B$8 -> 250125 | D37: =IF(D$13=Inputs!$C$4,1,0)*Inputs!$C$16*$B$8 -> 0 | E37: =IF(E$13=Inputs!$C$4,1,0)*Inputs!$C$16*$B$8 -> 0 | F37: =IF(F$13=Inputs!$C$4,1,0)*Inputs!$C$16*$B$8 -> 0 | G37: =IF(G$13=Inputs!$C$4,1,0)*Inputs!$C$16*$B$8 -> 0 | H37: =IF(H$13=Inputs!$C$4,1,0)*Inputs!$C$16*$B$8 -> 0 | I37: =IF(I$13=Inputs!$C$4,1,0)*Inputs!$C$16*$B$8 -> 0 | J37: =IF(J$13=Inputs!$C$4,1,0)*Inputs!$C$16*$B$8 -> 0 | ... AF37: =IF(AF$13=Inputs!$C$4,1,0)*Inputs!$C$16*$B$8 -> 0
A38: Maintenance — Oaky Creek Road | B38: =SUMPRODUCT(C38:AF38,$C$14:$AF$14) -> 3115845.2 | C38: =C17*Inputs!$C$23/100 -> 234668 | D38: =D17*Inputs!$C$23/100 -> 234668 | E38: =E17*Inputs!$C$23/100 -> 234668 | F38: =F17*Inputs!$C$23/100 -> 234668 | G38: =G17*Inputs!$C$23/100 -> 234668 | H38: =H17*Inputs!$C$23/100 -> 234668 | I38: =I17*Inputs!$C$23/100 -> 234668 | J38: =J17*Inputs!$C$23/100 -> 234668 | ... AF38: =AF17*Inputs!$C$23/100 -> 234668
A39: Maintenance — Percy Road | B39: =SUMPRODUCT(C39:AF39,$C$14:$AF$14) -> 831809.1 | C39: =C18*Inputs!$C$23/100 -> 62647.2 | D39: =D18*Inputs!$C$23/100 -> 62647.2 | E39: =E18*Inputs!$C$23/100 -> 62647.2 | F39: =F18*Inputs!$C$23/100 -> 62647.2 | G39: =G18*Inputs!$C$23/100 -> 62647.2 | H39: =H18*Inputs!$C$23/100 -> 62647.2 | I39: =I18*Inputs!$C$23/100 -> 62647.2 | J39: =J18*Inputs!$C$23/100 -> 62647.2 | ... AF39: =AF18*Inputs!$C$23/100 -> 62647.2
A40: Invasive grader grass spraying | B40: =SUMPRODUCT(C40:AF40,$C$14:$AF$14) -> 257491.41 | C40: =IF(C$13-Inputs!$C$4<2,Inputs!$C$25,Inputs!$C$26)*$B$7 -> 32250 | D40: =IF(D$13-Inputs!$C$4<2,Inputs!$C$25,Inputs!$C$26)*$B$7 -> 32250 | E40: =IF(E$13-Inputs!$C$4<2,Inputs!$C$25,Inputs!$C$26)*$B$7 -> 17200 | F40: =IF(F$13-Inputs!$C$4<2,Inputs!$C$25,Inputs!$C$26)*$B$7 -> 17200 | G40: =IF(G$13-Inputs!$C$4<2,Inputs!$C$25,Inputs!$C$26)*$B$7 -> 17200 | H40: =IF(H$13-Inputs!$C$4<2,Inputs!$C$25,Inputs!$C$26)*$B$7 -> 17200 | I40: =IF(I$13-Inputs!$C$4<2,Inputs!$C$25,Inputs!$C$26)*$B$7 -> 17200 | J40: =IF(J$13-Inputs!$C$4<2,Inputs!$C$25,Inputs!$C$26)*$B$7 -> 17200 | ... AF40: =IF(AF$13-Inputs!$C$4<2,Inputs!$C$25,Inputs!$C$26)*$B$7 -> 17200
A41: Woody weeds (broadleaf herbicide) | B41: =SUMPRODUCT(C41:AF41,$C$14:$AF$14) -> 182947.71 | C41: =CHOOSE(MIN(C$13-Inputs!$C$4+1,4),Inputs!$C$28,Inputs!$C$29,Inputs!$C$30,Inputs!$C$31)*$B$7 -> 58157.5 | D41: =CHOOSE(MIN(D$13-Inputs!$C$4+1,4),Inputs!$C$28,Inputs!$C$29,Inputs!$C$30,Inputs!$C$31)*$B$7 -> 24123 | E41: =CHOOSE(MIN(E$13-Inputs!$C$4+1,4),Inputs!$C$28,Inputs!$C$29,Inputs!$C$30,Inputs!$C$31)*$B$7 -> 13975 | F41: =CHOOSE(MIN(F$13-Inputs!$C$4+1,4),Inputs!$C$28,Inputs!$C$29,Inputs!$C$30,Inputs!$C$31)*$B$7 -> 8600 | G41: =CHOOSE(MIN(G$13-Inputs!$C$4+1,4),Inputs!$C$28,Inputs!$C$29,Inputs!$C$30,Inputs!$C$31)*$B$7 -> 8600 | H41: =CHOOSE(MIN(H$13-Inputs!$C$4+1,4),Inputs!$C$28,Inputs!$C$29,Inputs!$C$30,Inputs!$C$31)*$B$7 -> 8600 | I41: =CHOOSE(MIN(I$13-Inputs!$C$4+1,4),Inputs!$C$28,Inputs!$C$29,Inputs!$C$30,Inputs!$C$31)*$B$7 -> 8600 | J41: =CHOOSE(MIN(J$13-Inputs!$C$4+1,4),Inputs!$C$28,Inputs!$C$29,Inputs!$C$30,Inputs!$C$31)*$B$7 -> 8600 | ... AF41: =CHOOSE(MIN(AF$13-Inputs!$C$4+1,4),Inputs!$C$28,Inputs!$C$29,Inputs!$C$30,Inputs!$C$31)*$B$7 -> 8600
A42: Total financial costs | B42: =SUMPRODUCT(C42:AF42,$C$14:$AF$14) -> 5538668.4 | C42: =SUM(C35:C41) -> 1538297.7 | D42: =SUM(D35:D41) -> 353688.2 | E42: =SUM(E35:E41) -> 328490.2 | F42: =SUM(F35:F41) -> 323115.2 | G42: =SUM(G35:G41) -> 323115.2 | H42: =SUM(H35:H41) -> 323115.2 | I42: =SUM(I35:I41) -> 323115.2 | J42: =SUM(J35:J41) -> 323115.2 | ... AF42: =SUM(AF35:AF41) -> 323115.2
A43: Sediment delivered to reef (t/yr <20µm) | C43: =Inputs!$C$37*$B$7 -> 681.55 | D43: =Inputs!$C$37*$B$7 -> 681.55 | E43: =Inputs!$C$37*$B$7 -> 681.55 | F43: =Inputs!$C$37*$B$7 -> 681.55 | G43: =Inputs!$C$37*$B$7 -> 681.55 | H43: =Inputs!$C$37*$B$7 -> 681.55 | I43: =Inputs!$C$37*$B$7 -> 681.55 | J43: =Inputs!$C$37*$B$7 -> 681.55 | ... AF43: =Inputs!$C$37*$B$7 -> 681.55
A44: Cost of sediment delivery to the reef | B44: =SUMPRODUCT(C44:AF44,$C$14:$AF$14) -> 15575028 | C44: =C43*$B$10 -> 1173023.9 | D44: =D43*$B$10 -> 1173023.9 | E44: =E43*$B$10 -> 1173023.9 | F44: =F43*$B$10 -> 1173023.9 | G44: =G43*$B$10 -> 1173023.9 | H44: =H43*$B$10 -> 1173023.9 | I44: =I43*$B$10 -> 1173023.9 | J44: =J43*$B$10 -> 1173023.9 | ... AF44: =AF43*$B$10 -> 1173023.9
A45: Total costs (financial + environmental) | B45: =SUMPRODUCT(C45:AF45,$C$14:$AF$14) -> 21113697 | C45: =C42+C44 -> 2711321.6 | D45: =D42+D44 -> 1526712.1 | E45: =E42+E44 -> 1501514.1 | F45: =F42+F44 -> 1496139.1 | G45: =G42+G44 -> 1496139.1 | H45: =H42+H44 -> 1496139.1 | I45: =I42+I44 -> 1496139.1 | J45: =J42+J44 -> 1496139.1 | ... AF45: =AF42+AF44 -> 1496139.1
A47: Scenario 4: Full betterment (bitumen)
...
